Workbook

Sheet 00_통합대시보드
A1: 🚀 삼성 코딩테스트 & 정보보안기사 통합 진척도 대시보드
A2: 52주 학습 잔디밭 & 실시간 진도율 관제
A4: 🔥 1일 평균 풀이량 | O4: 📊 난이도별 풀이 (총 100제) | AC4: 💻 전체 진척 및 잔여량 | AQ4: 🛡️ 정보보안기사 필기
A5: =ROUND(COUNTIF('02_SWEA_통합_코딩테스트_DB'!$F$4:$F$1260, "<>") / 30, 2) & " 문제 / 일" | O5: D1:41 · D2:43 · D3:12 · D4:2 · D8:1 | AC5: =COUNTIF('02_SWEA_통합_코딩테스트_DB'!$F$4:$F$1260, "<>") & " / " & X37 & "제 (잔여 " & (X37 - COUNTIF('02_SWEA_통합_코딩테스트_DB'!$F$4:$F$1260, "<>")) & "제)" | AQ5: =COUNTIF('03_보안기사_필기_DB'!$I$4:$I$46, "<>") & " / 43섹션 (" & TEXT(COUNTIF('03_보안기사_필기_DB'!$I$4:$I$46, "<>")/43, "0.0%") & ")"
A6: 실활동 30일 기준 (9월: 3.1제/일) | O6: D1 100% · D2 75% · D3 5.6% · D4 1.0% | AC6: 전체 진도율 9.2% (전체 81일 기준 1.2제/일) | AQ6: ="1차 CBT D-" & (DATE(2027,2,15)-TODAY()) & " (02.15) | 2차 실기 D-" & (DATE(2027,4,10)-TODAY())
A8: 🌿 [52주 학습 잔디밭] 코딩테스트 & 보안기사 일일 학습 히트맵
A9: 월별 | C9: =TEXT(DATE(2026,8,24)+0*7, "yy.mm") | D9: =TEXT(DATE(2026,8,24)+1*7, "yy.mm") | E9: =TEXT(DATE(2026,8,24)+2*7, "yy.mm") | F9: =TEXT(DATE(2026,8,24)+3*7, "yy.mm") | G9: =TEXT(DATE(2026,8,24)+4*7, "yy.mm") | H9: =TEXT(DATE(2026,8,24)+5*7, "yy.mm") | I9: =TEXT(DATE(2026,8,24)+6*7, "yy.mm") | J9: =TEXT(DATE(2026,8,24)+7*7, "yy.mm") | K9: =TEXT(DATE(2026,8,24)+8*7, "yy.mm") | L9: =TEXT(DATE(2026,8,24)+9*7, "yy.mm") | M9: =TEXT(DATE(2026,8,24)+10*7, "yy.mm") | N9: =TEXT(DATE(2026,8,24)+11*7, "yy.mm") | O9: =TEXT(DATE(2026,8,24)+12*7, "yy.mm") | P9: =TEXT(DATE(2026,8,24)+13*7, "yy.mm") | Q9: =TEXT(DATE(2026,8,24)+14*7, "yy.mm") | R9: =TEXT(DATE(2026,8,24)+15*7, "yy.mm") | S9: =TEXT(DATE(2026,8,24)+16*7, "yy.mm") | T9: =TEXT(DATE(2026,8,24)+17*7, "yy.mm") | U9: =TEXT(DATE(2026,8,24)+18*7, "yy.mm") | V9: =TEXT(DATE(2026,8,24)+19*7, "yy.mm") | W9: =TEXT(DATE(2026,8,24)+20*7, "yy.mm") | X9: =TEXT(DATE(2026,8,24)+21*7, "yy.mm") | Y9: =TEXT(DATE(2026,8,24)+22*7, "yy.mm") | Z9: =TEXT(DATE(2026,8,24)+23*7, "yy.mm") | AA9: =TEXT(DATE(2026,8,24)+24*7, "yy.mm") | AB9: =TEXT(DATE(2026,8,24)+25*7, "yy.mm") | AC9: =TEXT(DATE(2026,8,24)+26*7, "yy.mm") | AD9: =TEXT(DATE(2026,8,24)+27*7, "yy.mm") | AE9: =TEXT(DATE(2026,8,24)+28*7, "yy.mm") | AF9: =TEXT(DATE(2026,8,24)+29*7, "yy.mm") | AG9: =TEXT(DATE(2026,8,24)+30*7, "yy.mm") | AH9: =TEXT(DATE(2026,8,24)+31*7, "yy.mm") | AI9: =TEXT(DATE(2026,8,24)+32*7, "yy.mm") | AJ9: =TEXT(DATE(2026,8,24)+33*7, "yy.mm") | AK9: =TEXT(DATE(2026,8,24)+34*7, "yy.mm") | AL9: =TEXT(DATE(2026,8,24)+35*7, "yy.mm") | AM9: =TEXT(DATE(2026,8,24)+36*7, "yy.mm") | AN9: =TEXT(DATE(2026,8,24)+37*7, "yy.mm") | AO9: =TEXT(DATE(2026,8,24)+38*7, "yy.mm") | AP9: =TEXT(DATE(2026,8,24)+39*7, "yy.mm") | AQ9: =TEXT(DATE(2026,8,24)+40*7, "yy.mm") | AR9: =TEXT(DATE(2026,8,24)+41*7, "yy.mm") | AS9: =TEXT(DATE(2026,8,24)+42*7, "yy.mm") | AT9: =TEXT(DATE(2026,8,24)+43*7, "yy.mm") | AU9: =TEXT(DATE(2026,8,24)+44*7, "yy.mm") | AV9: =TEXT(DATE(2026,8,24)+45*7, "yy.mm") | AW9: =TEXT(DATE(2026,8,24)+46*7, "yy.mm") | AX9: =TEXT(DATE(2026,8,24)+47*7, "yy.mm") | AY9: =TEXT(DATE(2026,8,24)+48*7, "yy.mm") | AZ9: =TEXT(DATE(2026,8,24)+49*7, "yy.mm") | BA9: =TEXT(DATE(2026,8,24)+50*7, "yy.mm") | BB9: =TEXT(DATE(2026,8,24)+51*7, "yy.mm") | BC9: =TEXT(DATE(2026,8,24)+52*7, "yy.mm")
A10: 주차 | C10: =IF(AND(DATE(2026,8,24)+0*7<=TODAY(), TODAY()<=DATE(2026,8,24)+0*7+6), "📍W01", "W01") | D10: =IF(AND(DATE(2026,8,24)+1*7<=TODAY(), TODAY()<=DATE(2026,8,24)+1*7+6), "📍W02", "W02") | E10: =IF(AND(DATE(2026,8,24)+2*7<=TODAY(), TODAY()<=DATE(2026,8,24)+2*7+6), "📍W03", "W03") | F10: =IF(AND(DATE(2026,8,24)+3*7<=TODAY(), TODAY()<=DATE(2026,8,24)+3*7+6), "📍W04", "W04") | G10: =IF(AND(DATE(2026,8,24)+4*7<=TODAY(), TODAY()<=DATE(2026,8,24)+4*7+6), "📍W05", "W05") | H10: =IF(AND(DATE(2026,8,24)+5*7<=TODAY(), TODAY()<=DATE(2026,8,24)+5*7+6), "📍W06", "W06") | I10: =IF(AND(DATE(2026,8,24)+6*7<=TODAY(), TODAY()<=DATE(2026,8,24)+6*7+6), "📍W07", "W07") | J10: =IF(AND(DATE(2026,8,24)+7*7<=TODAY(), TODAY()<=DATE(2026,8,24)+7*7+6), "📍W08", "W08") | K10: =IF(AND(DATE(2026,8,24)+8*7<=TODAY(), TODAY()<=DATE(2026,8,24)+8*7+6), "📍W09", "W09") | L10: =IF(AND(DATE(2026,8,24)+9*7<=TODAY(), TODAY()<=DATE(2026,8,24)+9*7+6), "📍W10", "W10") | M10: =IF(AND(DATE(2026,8,24)+10*7<=TODAY(), TODAY()<=DATE(2026,8,24)+10*7+6), "📍W11", "W11") | N10: =IF(AND(DATE(2026,8,24)+11*7<=TODAY(), TODAY()<=DATE(2026,8,24)+11*7+6), "📍W12", "W12") | O10: =IF(AND(DATE(2026,8,24)+12*7<=TODAY(), TODAY()<=DATE(2026,8,24)+12*7+6), "📍W13", "W13") | P10: =IF(AND(DATE(2026,8,24)+13*7<=TODAY(), TODAY()<=DATE(2026,8,24)+13*7+6), "📍W14", "W14") | Q10: =IF(AND(DATE(2026,8,24)+14*7<=TODAY(), TODAY()<=DATE(2026,8,24)+14*7+6), "📍W15", "W15") | R10: =IF(AND(DATE(2026,8,24)+15*7<=TODAY(), TODAY()<=DATE(2026,8,24)+15*7+6), "📍W16", "W16") | S10: =IF(AND(DATE(2026,8,24)+16*7<=TODAY(), TODAY()<=DATE(2026,8,24)+16*7+6), "📍W17", "W17") | T10: =IF(AND(DATE(2026,8,24)+17*7<=TODAY(), TODAY()<=DATE(2026,8,24)+17*7+6), "📍W18", "W18") | U10: =IF(AND(DATE(2026,8,24)+18*7<=TODAY(), TODAY()<=DATE(2026,8,24)+18*7+6), "📍W19", "W19") | V10: =IF(AND(DATE(2026,8,24)+19*7<=TODAY(), TODAY()<=DATE(2026,8,24)+19*7+6), "📍W20", "W20") | W10: =IF(AND(DATE(2026,8,24)+20*7<=TODAY(), TODAY()<=DATE(2026,8,24)+20*7+6), "📍W21", "W21") | X10: =IF(AND(DATE(2026,8,24)+21*7<=TODAY(), TODAY()<=DATE(2026,8,24)+21*7+6), "📍W22", "W22") | Y10: =IF(AND(DATE(2026,8,24)+22*7<=TODAY(), TODAY()<=DATE(2026,8,24)+22*7+6), "📍W23", "W23") | Z10: =IF(AND(DATE(2026,8,24)+23*7<=TODAY(), TODAY()<=DATE(2026,8,24)+23*7+6), "📍W24", "W24") | AA10: =IF(AND(DATE(2026,8,24)+24*7<=TODAY(), TODAY()<=DATE(2026,8,24)+24*7+6), "📍W25", "W25") | AB10: =IF(AND(DATE(2026,8,24)+25*7<=TODAY(), TODAY()<=DATE(2026,8,24)+25*7+6), "📍W26", "W26") | AC10: =IF(AND(DATE(2026,8,24)+26*7<=TODAY(), TODAY()<=DATE(2026,8,24)+26*7+6), "📍W27", "W27") | AD10: =IF(AND(DATE(2026,8,24)+27*7<=TODAY(), TODAY()<=DATE(2026,8,24)+27*7+6), "📍W28", "W28") | AE10: =IF(AND(DATE(2026,8,24)+28*7<=TODAY(), TODAY()<=DATE(2026,8,24)+28*7+6), "📍W29", "W29") | AF10: =IF(AND(DATE(2026,8,24)+29*7<=TODAY(), TODAY()<=DATE(2026,8,24)+29*7+6), "📍W30", "W30") | AG10: =IF(AND(DATE(2026,8,24)+30*7<=TODAY(), TODAY()<=DATE(2026,8,24)+30*7+6), "📍W31", "W31") | AH10: =IF(AND(DATE(2026,8,24)+31*7<=TODAY(), TODAY()<=DATE(2026,8,24)+31*7+6), "📍W32", "W32") | AI10: =IF(AND(DATE(2026,8,24)+32*7<=TODAY(), TODAY()<=DATE(2026,8,24)+32*7+6), "📍W33", "W33") | AJ10: =IF(AND(DATE(2026,8,24)+33*7<=TODAY(), TODAY()<=DATE(2026,8,24)+33*7+6), "📍W34", "W34") | AK10: =IF(AND(DATE(2026,8,24)+34*7<=TODAY(), TODAY()<=DATE(2026,8,24)+34*7+6), "📍W35", "W35") | AL10: =IF(AND(DATE(2026,8,24)+35*7<=TODAY(), TODAY()<=DATE(2026,8,24)+35*7+6), "📍W36", "W36") | AM10: =IF(AND(DATE(2026,8,24)+36*7<=TODAY(), TODAY()<=DATE(2026,8,24)+36*7+6), "📍W37", "W37") | AN10: =IF(AND(DATE(2026,8,24)+37*7<=TODAY(), TODAY()<=DATE(2026,8,24)+37*7+6), "📍W38", "W38") | AO10: =IF(AND(DATE(2026,8,24)+38*7<=TODAY(), TODAY()<=DATE(2026,8,24)+38*7+6), "📍W39", "W39") | AP10: =IF(AND(DATE(2026,8,24)+39*7<=TODAY(), TODAY()<=DATE(2026,8,24)+39*7+6), "📍W40", "W40") | AQ10: =IF(AND(DATE(2026,8,24)+40*7<=TODAY(), TODAY()<=DATE(2026,8,24)+40*7+6), "📍W41", "W41") | AR10: =IF(AND(DATE(2026,8,24)+41*7<=TODAY(), TODAY()<=DATE(2026,8,24)+41*7+6), "📍W42", "W42") | AS10: =IF(AND(DATE(2026,8,24)+42*7<=TODAY(), TODAY()<=DATE(2026,8,24)+42*7+6), "📍W43", "W43") | AT10: =IF(AND(DATE(2026,8,24)+43*7<=TODAY(), TODAY()<=DATE(2026,8,24)+43*7+6), "📍W44", "W44") | AU10: =IF(AND(DATE(2026,8,24)+44*7<=TODAY(), TODAY()<=DATE(2026,8,24)+44*7+6), "📍W45", "W45") | AV10: =IF(AND(DATE(2026,8,24)+45*7<=TODAY(), TODAY()<=DATE(2026,8,24)+45*7+6), "📍W46", "W46") | AW10: =IF(AND(DATE(2026,8,24)+46*7<=TODAY(), TODAY()<=DATE(2026,8,24)+46*7+6), "📍W47", "W47") | AX10: =IF(AND(DATE(2026,8,24)+47*7<=TODAY(), TODAY()<=DATE(2026,8,24)+47*7+6), "📍W48", "W48") | AY10: =IF(AND(DATE(2026,8,24)+48*7<=TODAY(), TODAY()<=DATE(2026,8,24)+48*7+6), "📍W49", "W49") | AZ10: =IF(AND(DATE(2026,8,24)+49*7<=TODAY(), TODAY()<=DATE(2026,8,24)+49*7+6), "📍W50", "W50") | BA10: =IF(AND(DATE(2026,8,24)+50*7<=TODAY(), TODAY()<=DATE(2026,8,24)+50*7+6), "📍W51", "W51") | BB10: =IF(AND(DATE(2026,8,24)+51*7<=TODAY(), TODAY()<=DATE(2026,8,24)+51*7+6), "📍W52", "W52") | BC10: =IF(AND(DATE(2026,8,24)+52*7<=TODAY(), TODAY()<=DATE(2026,8,24)+52*7+6), "📍W53", "W53")
A11: 월 (Mon) | C11: =COUNTIFS('02_SWEA_통합_코딩테스트_DB'!$F$4:$F$1260, DATE(2026,8,24)+0*7+0, '02_SWEA_통합_코딩테스트_DB'!$J$4:$J$1260, "<>보류*") + COUNTIFS('02_SWEA_통합_코딩테스트_DB'!$G$4:$G$1260, DATE(2026,8,24)+0*7+0, '02_SWEA_통합_코딩테스트_DB'!$J$4:$J$1260, "<>보류*") + COUNTIFS('02_SWEA_통합_코딩테스트_DB'!$H$4:$H$1260, DATE(2026,8,24)+0*7+0, '02_SWEA_통합_코딩테스트_DB'!$J$4:$J$1260, "<>보류*") + COUNTIFS('02_SWEA_통합_코딩테스트_DB'!$I$4:$I$1260, DATE(2026,8,24)+0*7+0, '02_SWEA_통합_코딩테스트_DB'!$J$4:$J$1260, "<>보류*") + COUNTIF('03_보안기사_필기_DB'!$I$4:$M$100, DATE(2026,8,24)+0*7+0) + COUNTIF('04_보안기사_실기_DB'!$G$4:$I$30, DATE(2026,8,24)+0*7+0) + COUNTIF('08_빅분기_필기_DB'!$I$4:$K$34, DATE(2026,8,24)+0*7+0) + COUNTIF('09_빅분기_실기_DB'!$H$4:$I$25, DATE(2026,8,24)+0*7+0) | D11: =COUNTIFS('02_SWEA_통합_코딩테스트_DB'!$F$4:$F$1260, DATE(2026,8,24)+1*7+0, '02_SWEA_통합_코딩테스트_DB'!$J$4:$J$1260, "<>보류*") + COUNTIFS('02_SWEA_통합_코딩테스트_DB'!$G$4:$G$1260, DATE(2026,8,24)+1*7+0, '02_SWEA_통합_코딩테스트_DB'!$J$4:$J$1260, "<>보류*") + COUNTIFS('02_SWEA_통합_코딩테스트_DB'!$H$4:$H$1260, DATE(2026,8,24)+1*7+0, '02_SWEA_통합_코딩테스트_DB'!$J$4:$J$1260, "<>보류*") + COUNTIFS('02_SWEA_통합_코딩테스트_DB'!$I$4:$I$1260, DATE(2026,8,24)+1*7+0, '02_SWEA_통합_코딩테스트_DB'!$J$4:$J$1260, "<>보류*") + COUNTIF('03_보안기사_필기_DB'!$I$4:$M$100, DATE(2026,8,24)+1*7+0) + COUNTIF('04_보안기사_실기_DB'!$G$4:$I$30, DATE(2026,8,24)+1*7+0) + COUNTIF('08_빅분기_필기_DB'!$I$4:$K$34, DATE(2026,8,24)+1*7+0) + COUNTIF('09_빅분기_실기_DB'!$H$4:$I$25, DATE(2026,8,24)+1*7+0) | E11: =COUNTIFS('02_SWEA_통합_코딩테스트_DB'!$F$4:$F$1260, DATE(2026,8,24)+2*7+0, '02_SWEA_통합_코딩테스트_DB'!$J$4:$J$1260, "<>보류*") + COUNTIFS('02_SWEA_통합_코딩테스트_DB'!$G$4:$G$1260, DATE(2026,8,24)+2*7+0, '02_SWEA_통합_코딩테스트_DB'!$J$4:$J$1260, "<>보류*") + COUNTIFS('02_SWEA_통합_코딩테스트_DB'!$H$4:$H$1260, DATE(2026,8,24)+2*7+0, '02_SWEA_통합_코딩테스트_DB'!$J$4:$J$1260, "<>보류*") + COUNTIFS('02_SWEA_통합_코딩테스트_DB'!$I$4:$I$1260, DATE(2026,8,24)+2*7+0, '02_SWEA_통합_코딩테스트_DB'!$J$4:$J$1260, "<>보류*") + COUNTIF('03_보안기사_필기_DB'!$I$4:$M$100, DATE(2026,8,24)+2*7+0) + COUNTIF('04_보안기사_실기_DB'!$G$4:$I$30, DATE(2026,8,24)+2*7+0) + COUNTIF('08_빅분기_필기_DB'!$I$4:$K$34, DATE(2026,8,24)+2*7+0) + COUNTIF('09_빅분기_실기_DB'!$H$4:$I$25, DATE(2026,8,24)+2*7+0) | F11: =COUNTIFS('02_SWEA_통합_코딩테스트_DB'!$F$4:$F$1260, DATE(2026,8,24)+3*7+0, '02_SWEA_통합_코딩테스트_DB'!$J$4:$J$1260, "<>보류*") + COUNTIFS('02_SWEA_통합_코딩테스트_DB'!$G$4:$G$1260, DATE(2026,8,24)+3*7+0, '02_SWEA_통합_코딩테스트_DB'!$J$4:$J$1260, "<>보류*") + COUNTIFS('02_SWEA_통합_코딩테스트_DB'!$H$4:$H$1260, DATE(2026,8,24)+3*7+0, '02_SWEA_통합_코딩테스트_DB'!$J$4:$J$1260, "<>보류*") + COUNTIFS('02_SWEA_통합_코딩테스트_DB'!$I$4:$I$1260, DATE(2026,8,24)+3*7+0, '02_SWEA_통합_코딩테스트_DB'!$J$4:$J$1260, "<>보류*") + COUNTIF('03_보안기사_필기_DB'!$I$4:$M$100, DATE(2026,8,24)+3*7+0) + COUNTIF('04_보안기사_실기_DB'!$G$4:$I$30, DATE(2026,8,24)+3*7+0) + COUNTIF('08_빅분기_필기_DB'!$I$4:$K$34, DATE(2026,8,24)+3*7+0) + COUNTIF('09_빅분기_실기_DB'!$H$4:$I$25, DATE(2026,8,24)+3*7+0) | G11: =COUNTIFS('02_SWEA_통합_코딩테스트_DB'!$F$4:$F$1260, DATE(2026,8,24)+4*7+0, '02_SWEA_통합_코딩테스트_DB'!$J$4:$J$1260, "<>보류*") + COUNTIFS('02_SWEA_통합_코딩테스트_DB'!$G$4:$G$1260, DATE(2026,8,24)+4*7+0, '02_SWEA_통합_코딩테스트_DB'!$J$4:$J$1260, "<>보류*") + COUNTIFS('02_SWEA_통합_코딩테스트_DB'!$H$4:$H$1260, DATE(2026,8,24)+4*7+0, '02_SWEA_통합_코딩테스트_DB'!$J$4:$J$1260, "<>보류*") + COUNTIFS('02_SWEA_통합_코딩테스트_DB'!$I$4:$I$1260, DATE(2026,8,24)+4*7+0, '02_SWEA_통합_코딩테스트_DB'!$J$4:$J$1260, "<>보류*") + COUNTIF('03_보안기사_필기_DB'!$I$4:$M$100, DATE(2026,8,24)+4*7+0) + COUNTIF('04_보안기사_실기_DB'!$G$4:$I$30, DATE(2026,8,24)+4*7+0) + COUNTIF('08_빅분기_필기_DB'!$I$4:$K$34, DATE(2026,8,24)+4*7+0) + COUNTIF('09_빅분기_실기_DB'!$H$4:$I$25, DATE(2026,8,24)+4*7+0) | H11: =COUNTIFS('02_SWEA_통합_코딩테스트_DB'!$F$4:$F$1260, DATE(2026,8,24)+5*7+0, '02_SWEA_통합_코딩테스트_DB'!$J$4:$J$1260, "<>보류*") + COUNTIFS('02_SWEA_통합_코딩테스트_DB'!$G$4:$G$1260, DATE(2026,8,24)+5*7+0, '02_SWEA_통합_코딩테스트_DB'!$J$4:$J$1260, "<>보류*") + COUNTIFS('02_SWEA_통합_코딩테스트_DB'!$H$4:$H$1260, DATE(2026,8,24)+5*7+0, '02_SWEA_통합_코딩테스트_DB'!$J$4:$J$1260, "<>보류*") + COUNTIFS('02_SWEA_통합_코딩테스트_DB'!$I$4:$I$1260, DATE(2026,8,24)+5*7+0, '02_SWEA_통합_코딩테스트_DB'!$J$4:$J$1260, "<>보류*") + COUNTIF('03_보안기사_필기_DB'!$I$4:$M$100, DATE(2026,8,24)+5*7+0) + COUNTIF('04_보안기사_실기_DB'!$G$4:$I$30, DATE(2026,8,24)+5*7+0) + COUNTIF('08_빅분기_필기_DB'!$I$4:$K$34, DATE(2026,8,24)+5*7+0) + COUNTIF('09_빅분기_실기_DB'!$H$4:$I$25, DATE(2026,8,24)+5*7+0) | I11: =COUNTIFS('02_SWEA_통합_코딩테스트_DB'!$F$4:$F$1260, DATE(2026,8,24)+6*7+0, '02_SWEA_통합_코딩테스트_DB'!$J$4:$J$1260, "<>보류*") + COUNTIFS('02_SWEA_통합_코딩테스트_DB'!$G$4:$G$1260, DATE(2026,8,24)+6*7+0, '02_SWEA_통합_코딩테스트_DB'!$J$4:$J$1260, "<>보류*") + COUNTIFS('02_SWEA_통합_코딩테스트_DB'!$H$4:$H$1260, DATE(2026,8,24)+6*7+0, '02_SWEA_통합_코딩테스트_DB'!$J$4:$J$1260, "<>보류*") + COUNTIFS('02_SWEA_통합_코딩테스트_DB'!$I$4:$I$1260, DATE(2026,8,24)+6*7+0, '02_SWEA_통합_코딩테스트_DB'!$J$4:$J$1260, "<>보류*") + COUNTIF('03_보안기사_필기_DB'!$I$4:$M$100, DATE(2026,8,24)+6*7+0) + COUNTIF('04_보안기사_실기_DB'!$G$4:$I$30, DATE(2026,8,24)+6*7+0) + COUNTIF('08_빅분기_필기_DB'!$I$4:$K$34, DATE(2026,8,24)+6*7+0) + COUNTIF('09_빅분기_실기_DB'!$H$4:$I$25, DATE(2026,8,24)+6*7+0) | J11: =COUNTIFS('02_SWEA_통합_코딩테스트_DB'!$F$4:$F$1260, DATE(2026,8,24)+7*7+0, '02_SWEA_통합_코딩테스트_DB'!$J$4:$J$1260, "<>보류*") + COUNTIFS('02_SWEA_통합_코딩테스트_DB'!$G$4:$G$1260, DATE(2026,8,24)+7*7+0, '02_SWEA_통합_코딩테스트_DB'!$J$4:$J$1260, "<>보류*") + COUNTIFS('02_SWEA_통합_코딩테스트_DB'!$H$4:$H$1260, DATE(2026,8,24)+7*7+0, '02_SWEA_통합_코딩테스트_DB'!$J$4:$J$1260, "<>보류*") + COUNTIFS('02_SWEA_통합_코딩테스트_DB'!$I$4:$I$1260, DATE(2026,8,24)+7*7+0, '02_SWEA_통합_코딩테스트_DB'!$J$4:$J$1260, "<>보류*") + COUNTIF('03_보안기사_필기_DB'!$I$4:$M$100, DATE(2026,8,24)+7*7+0) + COUNTIF('04_보안기사_실기_DB'!$G$4:$I$30, DATE(2026,8,24)+7*7+0) + COUNTIF('08_빅분기_필기_DB'!$I$4:$K$34, DATE(2026,8,24)+7*7+0) + COUNTIF('09_빅분기_실기_DB'!$H$4:$I$25, DATE(2026,8,24)+7*7+0) | K11: =COUNTIFS('02_SWEA_통합_코딩테스트_DB'!$F$4:$F$1260, DATE(2026,8,24)+8*7+0, '02_SWEA_통합_코딩테스트_DB'!$J$4:$J$1260, "<>보류*") + COUNTIFS('02_SWEA_통합_코딩테스트_DB'!$G$4:$G$1260, DATE(2026,8,24)+8*7+0, '02_SWEA_통합_코딩테스트_DB'!$J$4:$J$1260, "<>보류*") + COUNTIFS('02_SWEA_통합_코딩테스트_DB'!$H$4:$H$1260, DATE(2026,8,24)+8*7+0, '02_SWEA_통합_코딩테스트_DB'!$J$4:$J$1260, "<>보류*") + COUNTIFS('02_SWEA_통합_코딩테스트_DB'!$I$4:$I$1260, DATE(2026,8,24)+8*7+0, '02_SWEA_통합_코딩테스트_DB'!$J$4:$J$1260, "<>보류*") + COUNTIF('03_보안기사_필기_DB'!$I$4:$M$100, DATE(2026,8,24)+8*7+0) + COUNTIF('04_보안기사_실기_DB'!$G$4:$I$30, DATE(2026,8,24)+8*7+0) + COUNTIF('08_빅분기_필기_DB'!$I$4:$K$34, DATE(2026,8,24)+8*7+0) + COUNTIF('09_빅분기_실기_DB'!$H$4:$I$25, DATE(2026,8,24)+8*7+0) | L11: =COUNTIFS('02_SWEA_통합_코딩테스트_DB'!$F$4:$F$1260, DATE(2026,8,24)+9*7+0, '02_SWEA_통합_코딩테스트_DB'!$J$4:$J$1260, "<>보류*") + COUNTIFS('02_SWEA_통합_코딩테스트_DB'!$G$4:$G$1260, DATE(2026,8,24)+9*7+0, '02_SWEA_통합_코딩테스트_DB'!$J$4:$J$1260, "<>보류*") + COUNTIFS('02_SWEA_통합_코딩테스트_DB'!$H$4:$H$1260, DATE(2026,8,24)+9*7+0, '02_SWEA_통합_코딩테스트_DB'!$J$4:$J$1260, "<>보류*") + COUNTIFS('02_SWEA_통합_코딩테스트_DB'!$I$4:$I$1260, DATE(2026,8,24)+9*7+0, '02_SWEA_통합_코딩테스트_DB'!$J$4:$J$1260, "<>보류*") + COUNTIF('03_보안기사_필기_DB'!$I$4:$M$100, DATE(2026,8,24)+9*7+0) + COUNTIF('04_보안기사_실기_DB'!$G$4:$I$30, DATE(2026,8,24)+9*7+0) + COUNTIF('08_빅분기_필기_DB'!$I$4:$K$34, DATE(2026,8,24)+9*7+0) + COUNTIF('09_빅분기_실기_DB'!$H$4:$I$25, DATE(2026,8,24)+9*7+0) | M11: =COUNTIFS('02_SWEA_통합_코딩테스트_DB'!$F$4:$F$1260, DATE(2026,8,24)+10*7+0, '02_SWEA_통합_코딩테스트_DB'!$J$4:$J$1260, "<>보류*") + COUNTIFS('02_SWEA_통합_코딩테스트_DB'!$G$4:$G$1260, DATE(2026,8,24)+10*7+0, '02_SWEA_통합_코딩테스트_DB'!$J$4:$J$1260, "<>보류*") + COUNTIFS('02_SWEA_통합_코딩테스트_DB'!$H$4:$H$1260, DATE(2026,8,24)+10*7+0, '02_SWEA_통합_코딩테스트_DB'!$J$4:$J$1260, "<>보류*") + COUNTIFS('02_SWEA_통합_코딩테스트_DB'!$I$4:$I$1260, DATE(2026,8,24)+10*7+0, '02_SWEA_통합_코딩테스트_DB'!$J$4:$J$1260, "<>보류*") + COUNTIF('03_보안기사_필기_DB'!$I$4:$M$100, DATE(2026,8,24)+10*7+0) + COUNTIF('04_보안기사_실기_DB'!$G$4:$I$30, DATE(2026,8,24)+10*7+0) + COUNTIF('08_빅분기_필기_DB'!$I$4:$K$34, DATE(2026,8,24)+10*7+0) + COUNTIF('09_빅분기_실기_DB'!$H$4:$I$25, DATE(2026,8,24)+10*7+0) | N11: =COUNTIFS('02_SWEA_통합_코딩테스트_DB'!$F$4:$F$1260, DATE(2026,8,24)+11*7+0, '02_SWEA_통합_코딩테스트_DB'!$J$4:$J$1260, "<>보류*") + COUNTIFS('02_SWEA_통합_코딩테스트_DB'!$G$4:$G$1260, DATE(2026,8,24)+11*7+0, '02_SWEA_통합_코딩테스트_DB'!$J$4:$J$1260, "<>보류*") + COUNTIFS('02_SWEA_통합_코딩테스트_DB'!$H$4:$H$1260, DATE(2026,8,24)+11*7+0, '02_SWEA_통합_코딩테스트_DB'!$J$4:$J$1260, "<>보류*") + COUNTIFS('02_SWEA_통합_코딩테스트_DB'!$I$4:$I$1260, DATE(2026,8,24)+11*7+0, '02_SWEA_통합_코딩테스트_DB'!$J$4:$J$1260, "<>보류*") + COUNTIF('03_보안기사_필기_DB'!$I$4:$M$100, DATE(2026,8,24)+11*7+0) + COUNTIF('04_보안기사_실기_DB'!$G$4:$I$30, DATE(2026,8,24)+11*7+0) + COUNTIF('08_빅분기_필기_DB'!$I$4:$K$34, DATE(2026,8,24)+11*7+0) + COUNTIF('09_빅분기_실기_DB'!$H$4:$I$25, DATE(2026,8,24)+11*7+0) | O11: =COUNTIFS('02_SWEA_통합_코딩테스트_DB'!$F$4:$F$1260, DATE(2026,8,24)+12*7+0, '02_SWEA_통합_코딩테스트_DB'!$J$4:$J$1260, "<>보류*") + COUNTIFS('02_SWEA_통합_코딩테스트_DB'!$G$4:$G$1260, DATE(2026,8,24)+12*7+0, '02_SWEA_통합_코딩테스트_DB'!$J$4:$J$1260, "<>보류*") + COUNTIFS('02_SWEA_통합_코딩테스트_DB'!$H$4:$H$1260, DATE(2026,8,24)+12*7+0, '02_SWEA_통합_코딩테스트_DB'!$J$4:$J$1260, "<>보류*") + COUNTIFS('02_SWEA_통합_코딩테스트_DB'!$I$4:$I$1260, DATE(2026,8,24)+12*7+0, '02_SWEA_통합_코딩테스트_DB'!$J$4:$J$1260, "<>보류*") + COUNTIF('03_보안기사_필기_DB'!$I$4:$M$100, DATE(2026,8,24)+12*7+0) + COUNTIF('04_보안기사_실기_DB'!$G$4:$I$30, DATE(2026,8,24)+12*7+0) + COUNTIF('08_빅분기_필기_DB'!$I$4:$K$34, DATE(2026,8,24)+12*7+0) + COUNTIF('09_빅분기_실기_DB'!$H$4:$I$25, DATE(2026,8,24)+12*7+0) | P11: =COUNTIFS('02_SWEA_통합_코딩테스트_DB'!$F$4:$F$1260, DATE(2026,8,24)+13*7+0, '02_SWEA_통합_코딩테스트_DB'!$J$4:$J$1260, "<>보류*") + COUNTIFS('02_SWEA_통합_코딩테스트_DB'!$G$4:$G$1260, DATE(2026,8,24)+13*7+0, '02_SWEA_통합_코딩테스트_DB'!$J$4:$J$1260, "<>보류*") + COUNTIFS('02_SWEA_통합_코딩테스트_DB'!$H$4:$H$1260, DATE(2026,8,24)+13*7+0, '02_SWEA_통합_코딩테스트_DB'!$J$4:$J$1260, "<>보류*") + COUNTIFS('02_SWEA_통합_코딩테스트_DB'!$I$4:$I$1260, DATE(2026,8,24)+13*7+0, '02_SWEA_통합_코딩테스트_DB'!$J$4:$J$1260, "<>보류*") + COUNTIF('03_보안기사_필기_DB'!$I$4:$M$100, DATE(2026,8,24)+13*7+0) + COUNTIF('04_보안기사_실기_DB'!$G$4:$I$30, DATE(2026,8,24)+13*7+0) + COUNTIF('08_빅분기_필기_DB'!$I$4:$K$34, DATE(2026,8,24)+13*7+0) + COUNTIF('09_빅분기_실기_DB'!$H$4:$I$25, DATE(2026,8,24)+13*7+0) | Q11: =COUNTIFS('02_SWEA_통합_코딩테스트_DB'!$F$4:$F$1260, DATE(2026,8,24)+14*7+0, '02_SWEA_통합_코딩테스트_DB'!$J$4:$J$1260, "<>보류*") + COUNTIFS('02_SWEA_통합_코딩테스트_DB'!$G$4:$G$1260, DATE(2026,8,24)+14*7+0, '02_SWEA_통합_코딩테스트_DB'!$J$4:$J$1260, "<>보류*") + COUNTIFS('02_SWEA_통합_코딩테스트_DB'!$H$4:$H$1260, DATE(2026,8,24)+14*7+0, '02_SWEA_통합_코딩테스트_DB'!$J$4:$J$1260, "<>보류*") + COUNTIFS('02_SWEA_통합_코딩테스트_DB'!$I$4:$I$1260, DATE(2026,8,24)+14*7+0, '02_SWEA_통합_코딩테스트_DB'!$J$4:$J$1260, "<>보류*") + COUNTIF('03_보안기사_필기_DB'!$I$4:$M$100, DATE(2026,8,24)+14*7+0) + COUNTIF('04_보안기사_실기_DB'!$G$4:$I$30, DATE(2026,8,24)+14*7+0) + COUNTIF('08_빅분기_필기_DB'!$I$4:$K$34, DATE(2026,8,24)+14*7+0) + COUNTIF('09_빅분기_실기_DB'!$H$4:$I$25, DATE(2026,8,24)+14*7+0) | R11: =COUNTIFS('02_SWEA_통합_코딩테스트_DB'!$F$4:$F$1260, DATE(2026,8,24)+15*7+0, '02_SWEA_통합_코딩테스트_DB'!$J$4:$J$1260, "<>보류*") + COUNTIFS('02_SWEA_통합_코딩테스트_DB'!$G$4:$G$1260, DATE(2026,8,24)+15*7+0, '02_SWEA_통합_코딩테스트_DB'!$J$4:$J$1260, "<>보류*") + COUNTIFS('02_SWEA_통합_코딩테스트_DB'!$H$4:$H$1260, DATE(2026,8,24)+15*7+0, '02_SWEA_통합_코딩테스트_DB'!$J$4:$J$1260, "<>보류*") + COUNTIFS('02_SWEA_통합_코딩테스트_DB'!$I$4:$I$1260, DATE(2026,8,24)+15*7+0, '02_SWEA_통합_코딩테스트_DB'!$J$4:$J$1260, "<>보류*") + COUNTIF('03_보안기사_필기_DB'!$I$4:$M$100, DATE(2026,8,24)+15*7+0) + COUNTIF('04_보안기사_실기_DB'!$G$4:$I$30, DATE(2026,8,24)+15*7+0) + COUNTIF('08_빅분기_필기_DB'!$I$4:$K$34, DATE(2026,8,24)+15*7+0) + COUNTIF('09_빅분기_실기_DB'!$H$4:$I$25, DATE(2026,8,24)+15*7+0) | S11: =COUNTIFS('02_SWEA_통합_코딩테스트_DB'!$F$4:$F$1260, DATE(2026,8,24)+16*7+0, '02_SWEA_통합_코딩테스트_DB'!$J$4:$J$1260, "<>보류*") + COUNTIFS('02_SWEA_통합_코딩테스트_DB'!$G$4:$G$1260, DATE(2026,8,24)+16*7+0, '02_SWEA_통합_코딩테스트_DB'!$J$4:$J$1260, "<>보류*") + COUNTIFS('02_SWEA_통합_코딩테스트_DB'!$H$4:$H$1260, DATE(2026,8,24)+16*7+0, '02_SWEA_통합_코딩테스트_DB'!$J$4:$J$1260, "<>보류*") + COUNTIFS('02_SWEA_통합_코딩테스트_DB'!$I$4:$I$1260, DATE(2026,8,24)+16*7+0, '02_SWEA_통합_코딩테스트_DB'!$J$4:$J$1260, "<>보류*") + COUNTIF('03_보안기사_필기_DB'!$I$4:$M$100, DATE(2026,8,24)+16*7+0) + COUNTIF('04_보안기사_실기_DB'!$G$4:$I$30, DATE(2026,8,24)+16*7+0) + COUNTIF('08_빅분기_필기_DB'!$I$4:$K$34, DATE(2026,8,24)+16*7+0) + COUNTIF('09_빅분기_실기_DB'!$H$4:$I$25, DATE(2026,8,24)+16*7+0) | T11: =COUNTIFS('02_SWEA_통합_코딩테스트_DB'!$F$4:$F$1260, DATE(2026,8,24)+17*7+0, '02_SWEA_통합_코딩테스트_DB'!$J$4:$J$1260, "<>보류*") + COUNTIFS('02_SWEA_통합_코딩테스트_DB'!$G$4:$G$1260, DATE(2026,8,24)+17*7+0, '02_SWEA_통합_코딩테스트_DB'!$J$4:$J$1260, "<>보류*") + COUNTIFS('02_SWEA_통합_코딩테스트_DB'!$H$4:$H$1260, DATE(2026,8,24)+17*7+0, '02_SWEA_통합_코딩테스트_DB'!$J$4:$J$1260, "<>보류*") + COUNTIFS('02_SWEA_통합_코딩테스트_DB'!$I$4:$I$1260, DATE(2026,8,24)+17*7+0, '02_SWEA_통합_코딩테스트_DB'!$J$4:$J$1260, "<>보류*") + COUNTIF('03_보안기사_필기_DB'!$I$4:$M$100, DATE(2026,8,24)+17*7+0) + COUNTIF('04_보안기사_실기_DB'!$G$4:$I$30, DATE(2026,8,24)+17*7+0) + COUNTIF('08_빅분기_필기_DB'!$I$4:$K$34, DATE(2026,8,24)+17*7+0) + COUNTIF('09_빅분기_실기_DB'!$H$4:$I$25, DATE(2026,8,24)+17*7+0) | U11: =COUNTIFS('02_SWEA_통합_코딩테스트_DB'!$F$4:$F$1260, DATE(2026,8,24)+18*7+0, '02_SWEA_통합_코딩테스트_DB'!$J$4:$J$1260, "<>보류*") + COUNTIFS('02_SWEA_통합_코딩테스트_DB'!$G$4:$G$1260, DATE(2026,8,24)+18*7+0, '02_SWEA_통합_코딩테스트_DB'!$J$4:$J$1260, "<>보류*") + COUNTIFS('02_SWEA_통합_코딩테스트_DB'!$H$4:$H$1260, DATE(2026,8,24)+18*7+0, '02_SWEA_통합_코딩테스트_DB'!$J$4:$J$1260, "<>보류*") + COUNTIFS('02_SWEA_통합_코딩테스트_DB'!$I$4:$I$1260, DATE(2026,8,24)+18*7+0, '02_SWEA_통합_코딩테스트_DB'!$J$4:$J$1260, "<>보류*") + COUNTIF('03_보안기사_필기_DB'!$I$4:$M$100, DATE(2026,8,24)+18*7+0) + COUNTIF('04_보안기사_실기_DB'!$G$4:$I$30, DATE(2026,8,24)+18*7+0) + COUNTIF('08_빅분기_필기_DB'!$I$4:$K$34, DATE(2026,8,24)+18*7+0) + COUNTIF('09_빅분기_실기_DB'!$H$4:$I$25, DATE(2026,8,24)+18*7+0) | V11: =COUNTIFS('02_SWEA_통합_코딩테스트_DB'!$F$4:$F$1260, DATE(2026,8,24)+19*7+0, '02_SWEA_통합_코딩테스트_DB'!$J$4:$J$1260, "<>보류*") + COUNTIFS('02_SWEA_통합_코딩테스트_DB'!$G$4:$G$1260, DATE(2026,8,24)+19*7+0, '02_SWEA_통합_코딩테스트_DB'!$J$4:$J$1260, "<>보류*") + COUNTIFS('02_SWEA_통합_코딩테스트_DB'!$H$4:$H$1260, DATE(2026,8,24)+19*7+0, '02_SWEA_통합_코딩테스트_DB'!$J$4:$J$1260, "<>보류*") + COUNTIFS('02_SWEA_통합_코딩테스트_DB'!$I$4:$I$1260, DATE(2026,8,24)+19*7+0, '02_SWEA_통합_코딩테스트_DB'!$J$4:$J$1260, "<>보류*") + COUNTIF('03_보안기사_필기_DB'!$I$4:$M$100, DATE(2026,8,24)+19*7+0) + COUNTIF('04_보안기사_실기_DB'!$G$4:$I$30, DATE(2026,8,24)+19*7+0) + COUNTIF('08_빅분기_필기_DB'!$I$4:$K$34, DATE(2026,8,24)+19*7+0) + COUNTIF('09_빅분기_실기_DB'!$H$4:$I$25, DATE(2026,8,24)+19*7+0) | W11: =COUNTIFS('02_SWEA_통합_코딩테스트_DB'!$F$4:$F$1260, DATE(2026,8,24)+20*7+0, '02_SWEA_통합_코딩테스트_DB'!$J$4:$J$1260, "<>보류*") + COUNTIFS('02_SWEA_통합_코딩테스트_DB'!$G$4:$G$1260, DATE(2026,8,24)+20*7+0, '02_SWEA_통합_코딩테스트_DB'!$J$4:$J$1260, "<>보류*") + COUNTIFS('02_SWEA_통합_코딩테스트_DB'!$H$4:$H$1260, DATE(2026,8,24)+20*7+0, '02_SWEA_통합_코딩테스트_DB'!$J$4:$J$1260, "<>보류*") + COUNTIFS('02_SWEA_통합_코딩테스트_DB'!$I$4:$I$1260, DATE(2026,8,24)+20*7+0, '02_SWEA_통합_코딩테스트_DB'!$J$4:$J$1260, "<>보류*") + COUNTIF('03_보안기사_필기_DB'!$I$4:$M$100, DATE(2026,8,24)+20*7+0) + COUNTIF('04_보안기사_실기_DB'!$G$4:$I$30, DATE(2026,8,24)+20*7+0) + COUNTIF('08_빅분기_필기_DB'!$I$4:$K$34, DATE(2026,8,24)+20*7+0) + COUNTIF('09_빅분기_실기_DB'!$H$4:$I$25, DATE(2026,8,24)+20*7+0) | X11: =COUNTIFS('02_SWEA_통합_코딩테스트_DB'!$F$4:$F$1260, DATE(2026,8,24)+21*7+0, '02_SWEA_통합_코딩테스트_DB'!$J$4:$J$1260, "<>보류*") + COUNTIFS('02_SWEA_통합_코딩테스트_DB'!$G$4:$G$1260, DATE(2026,8,24)+21*7+0, '02_SWEA_통합_코딩테스트_DB'!$J$4:$J$1260, "<>보류*") + COUNTIFS('02_SWEA_통합_코딩테스트_DB'!$H$4:$H$1260, DATE(2026,8,24)+21*7+0, '02_SWEA_통합_코딩테스트_DB'!$J$4:$J$1260, "<>보류*") + COUNTIFS('02_SWEA_통합_코딩테스트_DB'!$I$4:$I$1260, DATE(2026,8,24)+21*7+0, '02_SWEA_통합_코딩테스트_DB'!$J$4:$J$1260, "<>보류*") + COUNTIF('03_보안기사_필기_DB'!$I$4:$M$100, DATE(2026,8,24)+21*7+0) + COUNTIF('04_보안기사_실기_DB'!$G$4:$I$30, DATE(2026,8,24)+21*7+0) + COUNTIF('08_빅분기_필기_DB'!$I$4:$K$34, DATE(2026,8,24)+21*7+0) + COUNTIF('09_빅분기_실기_DB'!$H$4:$I$25, DATE(2026,8,24)+21*7+0) | Y11: =COUNTIFS('02_SWEA_통합_코딩테스트_DB'!$F$4:$F$1260, DATE(2026,8,24)+22*7+0, '02_SWEA_통합_코딩테스트_DB'!$J$4:$J$1260, "<>보류*") + COUNTIFS('02_SWEA_통합_코딩테스트_DB'!$G$4:$G$1260, DATE(2026,8,24)+22*7+0, '02_SWEA_통합_코딩테스트_DB'!$J$4:$J$1260, "<>보류*") + COUNTIFS('02_SWEA_통합_코딩테스트_DB'!$H$4:$H$1260, DATE(2026,8,24)+22*7+0, '02_SWEA_통합_코딩테스트_DB'!$J$4:$J$1260, "<>보류*") + COUNTIFS('02_SWEA_통합_코딩테스트_DB'!$I$4:$I$1260, DATE(2026,8,24)+22*7+0, '02_SWEA_통합_코딩테스트_DB'!$J$4:$J$1260, "<>보류*") + COUNTIF('03_보안기사_필기_DB'!$I$4:$M$100, DATE(2026,8,24)+22*7+0) + COUNTIF('04_보안기사_실기_DB'!$G$4:$I$30, DATE(2026,8,24)+22*7+0) + COUNTIF('08_빅분기_필기_DB'!$I$4:$K$34, DATE(2026,8,24)+22*7+0) + COUNTIF('09_빅분기_실기_DB'!$H$4:$I$25, DATE(2026,8,24)+22*7+0) | Z11: =COUNTIFS('02_SWEA_통합_코딩테스트_DB'!$F$4:$F$1260, DATE(2026,8,24)+23*7+0, '02_SWEA_통합_코딩테스트_DB'!$J$4:$J$1260, "<>보류*") + COUNTIFS('02_SWEA_통합_코딩테스트_DB'!$G$4:$G$1260, DATE(2026,8,24)+23*7+0, '02_SWEA_통합_코딩테스트_DB'!$J$4:$J$1260, "<>보류*") + COUNTIFS('02_SWEA_통합_코딩테스트_DB'!$H$4:$H$1260, DATE(2026,8,24)+23*7+0, '02_SWEA_통합_코딩테스트_DB'!$J$4:$J$1260, "<>보류*") + COUNTIFS('02_SWEA_통합_코딩테스트_DB'!$I$4:$I$1260, DATE(2026,8,24)+23*7+0, '02_SWEA_통합_코딩테스트_DB'!$J$4:$J$1260, "<>보류*") + COUNTIF('03_보안기사_필기_DB'!$I$4:$M$100, DATE(2026,8,24)+23*7+0) + COUNTIF('04_보안기사_실기_DB'!$G$4:$I$30, DATE(2026,8,24)+23*7+0) + COUNTIF('08_빅분기_필기_DB'!$I$4:$K$34, DATE(2026,8,24)+23*7+0) + COUNTIF('09_빅분기_실기_DB'!$H$4:$I$25, DATE(2026,8,24)+23*7+0) | AA11: =COUNTIFS('02_SWEA_통합_코딩테스트_DB'!$F$4:$F$1260, DATE(2026,8,24)+24*7+0, '02_SWEA_통합_코딩테스트_DB'!$J$4:$J$1260, "<>보류*") + COUNTIFS('02_SWEA_통합_코딩테스트_DB'!$G$4:$G$1260, DATE(2026,8,24)+24*7+0, '02_SWEA_통합_코딩테스트_DB'!$J$4:$J$1260, "<>보류*") + COUNTIFS('02_SWEA_통합_코딩테스트_DB'!$H$4:$H$1260, DATE(2026,8,24)+24*7+0, '02_SWEA_통합_코딩테스트_DB'!$J$4:$J$1260, "<>보류*") + COUNTIFS('02_SWEA_통합_코딩테스트_DB'!$I$4:$I$1260, DATE(2026,8,24)+24*7+0, '02_SWEA_통합_코딩테스트_DB'!$J$4:$J$1260, "<>보류*") + COUNTIF('03_보안기사_필기_DB'!$I$4:$M$100, DATE(2026,8,24)+24*7+0) + COUNTIF('04_보안기사_실기_DB'!$G$4:$I$30, DATE(2026,8,24)+24*7+0) + COUNTIF('08_빅분기_필기_DB'!$I$4:$K$34, DATE(2026,8,24)+24*7+0) + COUNTIF('09_빅분기_실기_DB'!$H$4:$I$25, DATE(2026,8,24)+24*7+0) | AB11: =COUNTIFS('02_SWEA_통합_코딩테스트_DB'!$F$4:$F$1260, DATE(2026,8,24)+25*7+0, '02_SWEA_통합_코딩테스트_DB'!$J$4:$J$1260, "<>보류*") + COUNTIFS('02_SWEA_통합_코딩테스트_DB'!$G$4:$G$1260, DATE(2026,8,24)+25*7+0, '02_SWEA_통합_코딩테스트_DB'!$J$4:$J$1260, "<>보류*") + COUNTIFS('02_SWEA_통합_코딩테스트_DB'!$H$4:$H$1260, DATE(2026,8,24)+25*7+0, '02_SWEA_통합_코딩테스트_DB'!$J$4:$J$1260, "<>보류*") + COUNTIFS('02_SWEA_통합_코딩테스트_DB'!$I$4:$I$1260, DATE(2026,8,24)+25*7+0, '02_SWEA_통합_코딩테스트_DB'!$J$4:$J$1260, "<>보류*") + COUNTIF('03_보안기사_필기_DB'!$I$4:$M$100, DATE(2026,8,24)+25*7+0) + COUNTIF('04_보안기사_실기_DB'!$G$4:$I$30, DATE(2026,8,24)+25*7+0) + COUNTIF('08_빅분기_필기_DB'!$I$4:$K$34, DATE(2026,8,24)+25*7+0) + COUNTIF('09_빅분기_실기_DB'!$H$4:$I$25, DATE(2026,8,24)+25*7+0) | AC11: =COUNTIFS('02_SWEA_통합_코딩테스트_DB'!$F$4:$F$1260, DATE(2026,8,24)+26*7+0, '02_SWEA_통합_코딩테스트_DB'!$J$4:$J$1260, "<>보류*") + COUNTIFS('02_SWEA_통합_코딩테스트_DB'!$G$4:$G$1260, DATE(2026,8,24)+26*7+0, '02_SWEA_통합_코딩테스트_DB'!$J$4:$J$1260, "<>보류*") + COUNTIFS('02_SWEA_통합_코딩테스트_DB'!$H$4:$H$1260, DATE(2026,8,24)+26*7+0, '02_SWEA_통합_코딩테스트_DB'!$J$4:$J$1260, "<>보류*") + COUNTIFS('02_SWEA_통합_코딩테스트_DB'!$I$4:$I$1260, DATE(2026,8,24)+26*7+0, '02_SWEA_통합_코딩테스트_DB'!$J$4:$J$1260, "<>보류*") + COUNTIF('03_보안기사_필기_DB'!$I$4:$M$100, DATE(2026,8,24)+26*7+0) + COUNTIF('04_보안기사_실기_DB'!$G$4:$I$30, DATE(2026,8,24)+26*7+0) + COUNTIF('08_빅분기_필기_DB'!$I$4:$K$34, DATE(2026,8,24)+26*7+0) + COUNTIF('09_빅분기_실기_DB'!$H$4:$I$25, DATE(2026,8,24)+26*7+0) | AD11: =COUNTIFS('02_SWEA_통합_코딩테스트_DB'!$F$4:$F$1260, DATE(2026,8,24)+27*7+0, '02_SWEA_통합_코딩테스트_DB'!$J$4:$J$1260, "<>보류*") + COUNTIFS('02_SWEA_통합_코딩테스트_DB'!$G$4:$G$1260, DATE(2026,8,24)+27*7+0, '02_SWEA_통합_코딩테스트_DB'!$J$4:$J$1260, "<>보류*") + COUNTIFS('02_SWEA_통합_코딩테스트_DB'!$H$4:$H$1260, DATE(2026,8,24)+27*7+0, '02_SWEA_통합_코딩테스트_DB'!$J$4:$J$1260, "<>보류*") + COUNTIFS('02_SWEA_통합_코딩테스트_DB'!$I$4:$I$1260, DATE(2026,8,24)+27*7+0, '02_SWEA_통합_코딩테스트_DB'!$J$4:$J$1260, "<>보류*") + COUNTIF('03_보안기사_필기_DB'!$I$4:$M$100, DATE(2026,8,24)+27*7+0) + COUNTIF('04_보안기사_실기_DB'!$G$4:$I$30, DATE(2026,8,24)+27*7+0) + COUNTIF('08_빅분기_필기_DB'!$I$4:$K$34, DATE(2026,8,24)+27*7+0) + COUNTIF('09_빅분기_실기_DB'!$H$4:$I$25, DATE(2026,8,24)+27*7+0) | AE11: =COUNTIFS('02_SWEA_통합_코딩테스트_DB'!$F$4:$F$1260, DATE(2026,8,24)+28*7+0, '02_SWEA_통합_코딩테스트_DB'!$J$4:$J$1260, "<>보류*") + COUNTIFS('02_SWEA_통합_코딩테스트_DB'!$G$4:$G$1260, DATE(2026,8,24)+28*7+0, '02_SWEA_통합_코딩테스트_DB'!$J$4:$J$1260, "<>보류*") + COUNTIFS('02_SWEA_통합_코딩테스트_DB'!$H$4:$H$1260, DATE(2026,8,24)+28*7+0, '02_SWEA_통합_코딩테스트_DB'!$J$4:$J$1260, "<>보류*") + COUNTIFS('02_SWEA_통합_코딩테스트_DB'!$I$4:$I$1260, DATE(2026,8,24)+28*7+0, '02_SWEA_통합_코딩테스트_DB'!$J$4:$J$1260, "<>보류*") + COUNTIF('03_보안기사_필기_DB'!$I$4:$M$100, DATE(2026,8,24)+28*7+0) + COUNTIF('04_보안기사_실기_DB'!$G$4:$I$30, DATE(2026,8,24)+28*7+0) + COUNTIF('08_빅분기_필기_DB'!$I$4:$K$34, DATE(2026,8,24)+28*7+0) + COUNTIF('09_빅분기_실기_DB'!$H$4:$I$25, DATE(2026,8,24)+28*7+0) | AF11: =COUNTIFS('02_SWEA_통합_코딩테스트_DB'!$F$4:$F$1260, DATE(2026,8,24)+29*7+0, '02_SWEA_통합_코딩테스트_DB'!$J$4:$J$1260, "<>보류*") + COUNTIFS('02_SWEA_통합_코딩테스트_DB'!$G$4:$G$1260, DATE(2026,8,24)+29*7+0, '02_SWEA_통합_코딩테스트_DB'!$J$4:$J$1260, "<>보류*") + COUNTIFS('02_SWEA_통합_코딩테스트_DB'!$H$4:$H$1260, DATE(2026,8,24)+29*7+0, '02_SWEA_통합_코딩테스트_DB'!$J$4:$J$1260, "<>보류*") + COUNTIFS('02_SWEA_통합_코딩테스트_DB'!$I$4:$I$1260, DATE(2026,8,24)+29*7+0, '02_SWEA_통합_코딩테스트_DB'!$J$4:$J$1260, "<>보류*") + COUNTIF('03_보안기사_필기_DB'!$I$4:$M$100, DATE(2026,8,24)+29*7+0) + COUNTIF('04_보안기사_실기_DB'!$G$4:$I$30, DATE(2026,8,24)+29*7+0) + COUNTIF('08_빅분기_필기_DB'!$I$4:$K$34, DATE(2026,8,24)+29*7+0) + COUNTIF('09_빅분기_실기_DB'!$H$4:$I$25, DATE(2026,8,24)+29*7+0) | AG11: =COUNTIFS('02_SWEA_통합_코딩테스트_DB'!$F$4:$F$1260, DATE(2026,8,24)+30*7+0, '02_SWEA_통합_코딩테스트_DB'!$J$4:$J$1260, "<>보류*") + COUNTIFS('02_SWEA_통합_코딩테스트_DB'!$G$4:$G$1260, DATE(2026,8,24)+30*7+0, '02_SWEA_통합_코딩테스트_DB'!$J$4:$J$1260, "<>보류*") + COUNTIFS('02_SWEA_통합_코딩테스트_DB'!$H$4:$H$1260, DATE(2026,8,24)+30*7+0, '02_SWEA_통합_코딩테스트_DB'!$J$4:$J$1260, "<>보류*") + COUNTIFS('02_SWEA_통합_코딩테스트_DB'!$I$4:$I$1260, DATE(2026,8,24)+30*7+0, '02_SWEA_통합_코딩테스트_DB'!$J$4:$J$1260, "<>보류*") + COUNTIF('03_보안기사_필기_DB'!$I$4:$M$100, DATE(2026,8,24)+30*7+0) + COUNTIF('04_보안기사_실기_DB'!$G$4:$I$30, DATE(2026,8,24)+30*7+0) + COUNTIF('08_빅분기_필기_DB'!$I$4:$K$34, DATE(2026,8,24)+30*7+0) + COUNTIF('09_빅분기_실기_DB'!$H$4:$I$25, DATE(2026,8,24)+30*7+0) | AH11: =COUNTIFS('02_SWEA_통합_코딩테스트_DB'!$F$4:$F$1260, DATE(2026,8,24)+31*7+0, '02_SWEA_통합_코딩테스트_DB'!$J$4:$J$1260, "<>보류*") + COUNTIFS('02_SWEA_통합_코딩테스트_DB'!$G$4:$G$1260, DATE(2026,8,24)+31*7+0, '02_SWEA_통합_코딩테스트_DB'!$J$4:$J$1260, "<>보류*") + COUNTIFS('02_SWEA_통합_코딩테스트_DB'!$H$4:$H$1260, DATE(2026,8,24)+31*7+0, '02_SWEA_통합_코딩테스트_DB'!$J$4:$J$1260, "<>보류*") + COUNTIFS('02_SWEA_통합_코딩테스트_DB'!$I$4:$I$1260, DATE(2026,8,24)+31*7+0, '02_SWEA_통합_코딩테스트_DB'!$J$4:$J$1260, "<>보류*") + COUNTIF('03_보안기사_필기_DB'!$I$4:$M$100, DATE(2026,8,24)+31*7+0) + COUNTIF('04_보안기사_실기_DB'!$G$4:$I$30, DATE(2026,8,24)+31*7+0) + COUNTIF('08_빅분기_필기_DB'!$I$4:$K$34, DATE(2026,8,24)+31*7+0) + COUNTIF('09_빅분기_실기_DB'!$H$4:$I$25, DATE(2026,8,24)+31*7+0) | AI11: =COUNTIFS('02_SWEA_통합_코딩테스트_DB'!$F$4:$F$1260, DATE(2026,8,24)+32*7+0, '02_SWEA_통합_코딩테스트_DB'!$J$4:$J$1260, "<>보류*") + COUNTIFS('02_SWEA_통합_코딩테스트_DB'!$G$4:$G$1260, DATE(2026,8,24)+32*7+0, '02_SWEA_통합_코딩테스트_DB'!$J$4:$J$1260, "<>보류*") + COUNTIFS('02_SWEA_통합_코딩테스트_DB'!$H$4:$H$1260, DATE(2026,8,24)+32*7+0, '02_SWEA_통합_코딩테스트_DB'!$J$4:$J$1260, "<>보류*") + COUNTIFS('02_SWEA_통합_코딩테스트_DB'!$I$4:$I$1260, DATE(2026,8,24)+32*7+0, '02_SWEA_통합_코딩테스트_DB'!$J$4:$J$1260, "<>보류*") + COUNTIF('03_보안기사_필기_DB'!$I$4:$M$100, DATE(2026,8,24)+32*7+0) + COUNTIF('04_보안기사_실기_DB'!$G$4:$I$30, DATE(2026,8,24)+32*7+0) + COUNTIF('08_빅분기_필기_DB'!$I$4:$K$34, DATE(2026,8,24)+32*7+0) + COUNTIF('09_빅분기_실기_DB'!$H$4:$I$25, DATE(2026,8,24)+32*7+0) | AJ11: =COUNTIFS('02_SWEA_통합_코딩테스트_DB'!$F$4:$F$1260, DATE(2026,8,24)+33*7+0, '02_SWEA_통합_코딩테스트_DB'!$J$4:$J$1260, "<>보류*") + COUNTIFS('02_SWEA_통합_코딩테스트_DB'!$G$4:$G$1260, DATE(2026,8,24)+33*7+0, '02_SWEA_통합_코딩테스트_DB'!$J$4:$J$1260, "<>보류*") + COUNTIFS('02_SWEA_통합_코딩테스트_DB'!$H$4:$H$1260, DATE(2026,8,24)+33*7+0, '02_SWEA_통합_코딩테스트_DB'!$J$4:$J$1260, "<>보류*") + COUNTIFS('02_SWEA_통합_코딩테스트_DB'!$I$4:$I$1260, DATE(2026,8,24)+33*7+0, '02_SWEA_통합_코딩테스트_DB'!$J$4:$J$1260, "<>보류*") + COUNTIF('03_보안기사_필기_DB'!$I$4:$M$100, DATE(2026,8,24)+33*7+0) + COUNTIF('04_보안기사_실기_DB'!$G$4:$I$30, DATE(2026,8,24)+33*7+0) + COUNTIF('08_빅분기_필기_DB'!$I$4:$K$34, DATE(2026,8,24)+33*7+0) + COUNTIF('09_빅분기_실기_DB'!$H$4:$I$25, DATE(2026,8,24)+33*7+0) | AK11: =COUNTIFS('02_SWEA_통합_코딩테스트_DB'!$F$4:$F$1260, DATE(2026,8,24)+34*7+0, '02_SWEA_통합_코딩테스트_DB'!$J$4:$J$1260, "<>보류*") + COUNTIFS('02_SWEA_통합_코딩테스트_DB'!$G$4:$G$1260, DATE(2026,8,24)+34*7+0, '02_SWEA_통합_코딩테스트_DB'!$J$4:$J$1260, "<>보류*") + COUNTIFS('02_SWEA_통합_코딩테스트_DB'!$H$4:$H$1260, DATE(2026,8,24)+34*7+0, '02_SWEA_통합_코딩테스트_DB'!$J$4:$J$1260, "<>보류*") + COUNTIFS('02_SWEA_통합_코딩테스트_DB'!$I$4:$I$1260, DATE(2026,8,24)+34*7+0, '02_SWEA_통합_코딩테스트_DB'!$J$4:$J$1260, "<>보류*") + COUNTIF('03_보안기사_필기_DB'!$I$4:$M$100, DATE(2026,8,24)+34*7+0) + COUNTIF('04_보안기사_실기_DB'!$G$4:$I$30, DATE(2026,8,24)+34*7+0) + COUNTIF('08_빅분기_필기_DB'!$I$4:$K$34, DATE(2026,8,24)+34*7+0) + COUNTIF('09_빅분기_실기_DB'!$H$4:$I$25, DATE(2026,8,24)+34*7+0) | AL11: =COUNTIFS('02_SWEA_통합_코딩테스트_DB'!$F$4:$F$1260, DATE(2026,8,24)+35*7+0, '02_SWEA_통합_코딩테스트_DB'!$J$4:$J$1260, "<>보류*") + COUNTIFS('02_SWEA_통합_코딩테스트_DB'!$G$4:$G$1260, DATE(2026,8,24)+35*7+0, '02_SWEA_통합_코딩테스트_DB'!$J$4:$J$1260, "<>보류*") + COUNTIFS('02_SWEA_통합_코딩테스트_DB'!$H$4:$H$1260, DATE(2026,8,24)+35*7+0, '02_SWEA_통합_코딩테스트_DB'!$J$4:$J$1260, "<>보류*") + COUNTIFS('02_SWEA_통합_코딩테스트_DB'!$I$4:$I$1260, DATE(2026,8,24)+35*7+0, '02_SWEA_통합_코딩테스트_DB'!$J$4:$J$1260, "<>보류*") + COUNTIF('03_보안기사_필기_DB'!$I$4:$M$100, DATE(2026,8,24)+35*7+0) + COUNTIF('04_보안기사_실기_DB'!$G$4:$I$30, DATE(2026,8,24)+35*7+0) + COUNTIF('08_빅분기_필기_DB'!$I$4:$K$34, DATE(2026,8,24)+35*7+0) + COUNTIF('09_빅분기_실기_DB'!$H$4:$I$25, DATE(2026,8,24)+35*7+0) | AM11: =COUNTIFS('02_SWEA_통합_코딩테스트_DB'!$F$4:$F$1260, DATE(2026,8,24)+36*7+0, '02_SWEA_통합_코딩테스트_DB'!$J$4:$J$1260, "<>보류*") + COUNTIFS('02_SWEA_통합_코딩테스트_DB'!$G$4:$G$1260, DATE(2026,8,24)+36*7+0, '02_SWEA_통합_코딩테스트_DB'!$J$4:$J$1260, "<>보류*") + COUNTIFS('02_SWEA_통합_코딩테스트_DB'!$H$4:$H$1260, DATE(2026,8,24)+36*7+0, '02_SWEA_통합_코딩테스트_DB'!$J$4:$J$1260, "<>보류*") + COUNTIFS('02_SWEA_통합_코딩테스트_DB'!$I$4:$I$1260, DATE(2026,8,24)+36*7+0, '02_SWEA_통합_코딩테스트_DB'!$J$4:$J$1260, "<>보류*") + COUNTIF('03_보안기사_필기_DB'!$I$4:$M$100, DATE(2026,8,24)+36*7+0) + COUNTIF('04_보안기사_실기_DB'!$G$4:$I$30, DATE(2026,8,24)+36*7+0) + COUNTIF('08_빅분기_필기_DB'!$I$4:$K$34, DATE(2026,8,24)+36*7+0) + COUNTIF('09_빅분기_실기_DB'!$H$4:$I$25, DATE(2026,8,24)+36*7+0) | AN11: =COUNTIFS('02_SWEA_통합_코딩테스트_DB'!$F$4:$F$1260, DATE(2026,8,24)+37*7+0, '02_SWEA_통합_코딩테스트_DB'!$J$4:$J$1260, "<>보류*") + COUNTIFS('02_SWEA_통합_코딩테스트_DB'!$G$4:$G$1260, DATE(2026,8,24)+37*7+0, '02_SWEA_통합_코딩테스트_DB'!$J$4:$J$1260, "<>보류*") + COUNTIFS('02_SWEA_통합_코딩테스트_DB'!$H$4:$H$1260, DATE(2026,8,24)+37*7+0, '02_SWEA_통합_코딩테스트_DB'!$J$4:$J$1260, "<>보류*") + COUNTIFS('02_SWEA_통합_코딩테스트_DB'!$I$4:$I$1260, DATE(2026,8,24)+37*7+0, '02_SWEA_통합_코딩테스트_DB'!$J$4:$J$1260, "<>보류*") + COUNTIF('03_보안기사_필기_DB'!$I$4:$M$100, DATE(2026,8,24)+37*7+0) + COUNTIF('04_보안기사_실기_DB'!$G$4:$I$30, DATE(2026,8,24)+37*7+0) + COUNTIF('08_빅분기_필기_DB'!$I$4:$K$34, DATE(2026,8,24)+37*7+0) + COUNTIF('09_빅분기_실기_DB'!$H$4:$I$25, DATE(2026,8,24)+37*7+0) | AO11: =COUNTIFS('02_SWEA_통합_코딩테스트_DB'!$F$4:$F$1260, DATE(2026,8,24)+38*7+0, '02_SWEA_통합_코딩테스트_DB'!$J$4:$J$1260, "<>보류*") + COUNTIFS('02_SWEA_통합_코딩테스트_DB'!$G$4:$G$1260, DATE(2026,8,24)+38*7+0, '02_SWEA_통합_코딩테스트_DB'!$J$4:$J$1260, "<>보류*") + COUNTIFS('02_SWEA_통합_코딩테스트_DB'!$H$4:$H$1260, DATE(2026,8,24)+38*7+0, '02_SWEA_통합_코딩테스트_DB'!$J$4:$J$1260, "<>보류*") + COUNTIFS('02_SWEA_통합_코딩테스트_DB'!$I$4:$I$1260, DATE(2026,8,24)+38*7+0, '02_SWEA_통합_코딩테스트_DB'!$J$4:$J$1260, "<>보류*") + COUNTIF('03_보안기사_필기_DB'!$I$4:$M$100, DATE(2026,8,24)+38*7+0) + COUNTIF('04_보안기사_실기_DB'!$G$4:$I$30, DATE(2026,8,24)+38*7+0) + COUNTIF('08_빅분기_필기_DB'!$I$4:$K$34, DATE(2026,8,24)+38*7+0) + COUNTIF('09_빅분기_실기_DB'!$H$4:$I$25, DATE(2026,8,24)+38*7+0) | AP11: =COUNTIFS('02_SWEA_통합_코딩테스트_DB'!$F$4:$F$1260, DATE(2026,8,24)+39*7+0, '02_SWEA_통합_코딩테스트_DB'!$J$4:$J$1260, "<>보류*") + COUNTIFS('02_SWEA_통합_코딩테스트_DB'!$G$4:$G$1260, DATE(2026,8,24)+39*7+0, '02_SWEA_통합_코딩테스트_DB'!$J$4:$J$1260, "<>보류*") + COUNTIFS('02_SWEA_통합_코딩테스트_DB'!$H$4:$H$1260, DATE(2026,8,24)+39*7+0, '02_SWEA_통합_코딩테스트_DB'!$J$4:$J$1260, "<>보류*") + COUNTIFS('02_SWEA_통합_코딩테스트_DB'!$I$4:$I$1260, DATE(2026,8,24)+39*7+0, '02_SWEA_통합_코딩테스트_DB'!$J$4:$J$1260, "<>보류*") + COUNTIF('03_보안기사_필기_DB'!$I$4:$M$100, DATE(2026,8,24)+39*7+0) + COUNTIF('04_보안기사_실기_DB'!$G$4:$I$30, DATE(2026,8,24)+39*7+0) + COUNTIF('08_빅분기_필기_DB'!$I$4:$K$34, DATE(2026,8,24)+39*7+0) + COUNTIF('09_빅분기_실기_DB'!$H$4:$I$25, DATE(2026,8,24)+39*7+0) | AQ11: =COUNTIFS('02_SWEA_통합_코딩테스트_DB'!$F$4:$F$1260, DATE(2026,8,24)+40*7+0, '02_SWEA_통합_코딩테스트_DB'!$J$4:$J$1260, "<>보류*") + COUNTIFS('02_SWEA_통합_코딩테스트_DB'!$G$4:$G$1260, DATE(2026,8,24)+40*7+0, '02_SWEA_통합_코딩테스트_DB'!$J$4:$J$1260, "<>보류*") + COUNTIFS('02_SWEA_통합_코딩테스트_DB'!$H$4:$H$1260, DATE(2026,8,24)+40*7+0, '02_SWEA_통합_코딩테스트_DB'!$J$4:$J$1260, "<>보류*") + COUNTIFS('02_SWEA_통합_코딩테스트_DB'!$I$4:$I$1260, DATE(2026,8,24)+40*7+0, '02_SWEA_통합_코딩테스트_DB'!$J$4:$J$1260, "<>보류*") + COUNTIF('03_보안기사_필기_DB'!$I$4:$M$100, DATE(2026,8,24)+40*7+0) + COUNTIF('04_보안기사_실기_DB'!$G$4:$I$30, DATE(2026,8,24)+40*7+0) + COUNTIF('08_빅분기_필기_DB'!$I$4:$K$34, DATE(2026,8,24)+40*7+0) + COUNTIF('09_빅분기_실기_DB'!$H$4:$I$25, DATE(2026,8,24)+40*7+0) | AR11: =COUNTIFS('02_SWEA_통합_코딩테스트_DB'!$F$4:$F$1260, DATE(2026,8,24)+41*7+0, '02_SWEA_통합_코딩테스트_DB'!$J$4:$J$1260, "<>보류*") + COUNTIFS('02_SWEA_통합_코딩테스트_DB'!$G$4:$G$1260, DATE(2026,8,24)+41*7+0, '02_SWEA_통합_코딩테스트_DB'!$J$4:$J$1260, "<>보류*") + COUNTIFS('02_SWEA_통합_코딩테스트_DB'!$H$4:$H$1260, DATE(2026,8,24)+41*7+0, '02_SWEA_통합_코딩테스트_DB'!$J$4:$J$1260, "<>보류*") + COUNTIFS('02_SWEA_통합_코딩테스트_DB'!$I$4:$I$1260, DATE(2026,8,24)+41*7+0, '02_SWEA_통합_코딩테스트_DB'!$J$4:$J$1260, "<>보류*") + COUNTIF('03_보안기사_필기_DB'!$I$4:$M$100, DATE(2026,8,24)+41*7+0) + COUNTIF('04_보안기사_실기_DB'!$G$4:$I$30, DATE(2026,8,24)+41*7+0) + COUNTIF('08_빅분기_필기_DB'!$I$4:$K$34, DATE(2026,8,24)+41*7+0) + COUNTIF('09_빅분기_실기_DB'!$H$4:$I$25, DATE(2026,8,24)+41*7+0) | AS11: =COUNTIFS('02_SWEA_통합_코딩테스트_DB'!$F$4:$F$1260, DATE(2026,8,24)+42*7+0, '02_SWEA_통합_코딩테스트_DB'!$J$4:$J$1260, "<>보류*") + COUNTIFS('02_SWEA_통합_코딩테스트_DB'!$G$4:$G$1260, DATE(2026,8,24)+42*7+0, '02_SWEA_통합_코딩테스트_DB'!$J$4:$J$1260, "<>보류*") + COUNTIFS('02_SWEA_통합_코딩테스트_DB'!$H$4:$H$1260, DATE(2026,8,24)+42*7+0, '02_SWEA_통합_코딩테스트_DB'!$J$4:$J$1260, "<>보류*") + COUNTIFS('02_SWEA_통합_코딩테스트_DB'!$I$4:$I$1260, DATE(2026,8,24)+42*7+0, '02_SWEA_통합_코딩테스트_DB'!$J$4:$J$1260, "<>보류*") + COUNTIF('03_보안기사_필기_DB'!$I$4:$M$100, DATE(2026,8,24)+42*7+0) + COUNTIF('04_보안기사_실기_DB'!$G$4:$I$30, DATE(2026,8,24)+42*7+0) + COUNTIF('08_빅분기_필기_DB'!$I$4:$K$34, DATE(2026,8,24)+42*7+0) + COUNTIF('09_빅분기_실기_DB'!$H$4:$I$25, DATE(2026,8,24)+42*7+0) | AT11: =COUNTIFS('02_SWEA_통합_코딩테스트_DB'!$F$4:$F$1260, DATE(2026,8,24)+43*7+0, '02_SWEA_통합_코딩테스트_DB'!$J$4:$J$1260, "<>보류*") + COUNTIFS('02_SWEA_통합_코딩테스트_DB'!$G$4:$G$1260, DATE(2026,8,24)+43*7+0, '02_SWEA_통합_코딩테스트_DB'!$J$4:$J$1260, "<>보류*") + COUNTIFS('02_SWEA_통합_코딩테스트_DB'!$H$4:$H$1260, DATE(2026,8,24)+43*7+0, '02_SWEA_통합_코딩테스트_DB'!$J$4:$J$1260, "<>보류*") + COUNTIFS('02_SWEA_통합_코딩테스트_DB'!$I$4:$I$1260, DATE(2026,8,24)+43*7+0, '02_SWEA_통합_코딩테스트_DB'!$J$4:$J$1260, "<>보류*") + COUNTIF('03_보안기사_필기_DB'!$I$4:$M$100, DATE(2026,8,24)+43*7+0) + COUNTIF('04_보안기사_실기_DB'!$G$4:$I$30, DATE(2026,8,24)+43*7+0) + COUNTIF('08_빅분기_필기_DB'!$I$4:$K$34, DATE(2026,8,24)+43*7+0) + COUNTIF('09_빅분기_실기_DB'!$H$4:$I$25, DATE(2026,8,24)+43*7+0) | AU11: =COUNTIFS('02_SWEA_통합_코딩테스트_DB'!$F$4:$F$1260, DATE(2026,8,24)+44*7+0, '02_SWEA_통합_코딩테스트_DB'!$J$4:$J$1260, "<>보류*") + COUNTIFS('02_SWEA_통합_코딩테스트_DB'!$G$4:$G$1260, DATE(2026,8,24)+44*7+0, '02_SWEA_통합_코딩테스트_DB'!$J$4:$J$1260, "<>보류*") + COUNTIFS('02_SWEA_통합_코딩테스트_DB'!$H$4:$H$1260, DATE(2026,8,24)+44*7+0, '02_SWEA_통합_코딩테스트_DB'!$J$4:$J$1260, "<>보류*") + COUNTIFS('02_SWEA_통합_코딩테스트_DB'!$I$4:$I$1260, DATE(2026,8,24)+44*7+0, '02_SWEA_통합_코딩테스트_DB'!$J$4:$J$1260, "<>보류*") + COUNTIF('03_보안기사_필기_DB'!$I$4:$M$100, DATE(2026,8,24)+44*7+0) + COUNTIF('04_보안기사_실기_DB'!$G$4:$I$30, DATE(2026,8,24)+44*7+0) + COUNTIF('08_빅분기_필기_DB'!$I$4:$K$34, DATE(2026,8,24)+44*7+0) + COUNTIF('09_빅분기_실기_DB'!$H$4:$I$25, DATE(2026,8,24)+44*7+0) | AV11: =COUNTIFS('02_SWEA_통합_코딩테스트_DB'!$F$4:$F$1260, DATE(2026,8,24)+45*7+0, '02_SWEA_통합_코딩테스트_DB'!$J$4:$J$1260, "<>보류*") + COUNTIFS('02_SWEA_통합_코딩테스트_DB'!$G$4:$G$1260, DATE(2026,8,24)+45*7+0, '02_SWEA_통합_코딩테스트_DB'!$J$4:$J$1260, "<>보류*") + COUNTIFS('02_SWEA_통합_코딩테스트_DB'!$H$4:$H$1260, DATE(2026,8,24)+45*7+0, '02_SWEA_통합_코딩테스트_DB'!$J$4:$J$1260, "<>보류*") + COUNTIFS('02_SWEA_통합_코딩테스트_DB'!$I$4:$I$1260, DATE(2026,8,24)+45*7+0, '02_SWEA_통합_코딩테스트_DB'!$J$4:$J$1260, "<>보류*") + COUNTIF('03_보안기사_필기_DB'!$I$4:$M$100, DATE(2026,8,24)+45*7+0) + COUNTIF('04_보안기사_실기_DB'!$G$4:$I$30, DATE(2026,8,24)+45*7+0) + COUNTIF('08_빅분기_필기_DB'!$I$4:$K$34, DATE(2026,8,24)+45*7+0) + COUNTIF('09_빅분기_실기_DB'!$H$4:$I$25, DATE(2026,8,24)+45*7+0) | AW11: =COUNTIFS('02_SWEA_통합_코딩테스트_DB'!$F$4:$F$1260, DATE(2026,8,24)+46*7+0, '02_SWEA_통합_코딩테스트_DB'!$J$4:$J$1260, "<>보류*") + COUNTIFS('02_SWEA_통합_코딩테스트_DB'!$G$4:$G$1260, DATE(2026,8,24)+46*7+0, '02_SWEA_통합_코딩테스트_DB'!$J$4:$J$1260, "<>보류*") + COUNTIFS('02_SWEA_통합_코딩테스트_DB'!$H$4:$H$1260, DATE(2026,8,24)+46*7+0, '02_SWEA_통합_코딩테스트_DB'!$J$4:$J$1260, "<>보류*") + COUNTIFS('02_SWEA_통합_코딩테스트_DB'!$I$4:$I$1260, DATE(2026,8,24)+46*7+0, '02_SWEA_통합_코딩테스트_DB'!$J$4:$J$1260, "<>보류*") + COUNTIF('03_보안기사_필기_DB'!$I$4:$M$100, DATE(2026,8,24)+46*7+0) + COUNTIF('04_보안기사_실기_DB'!$G$4:$I$30, DATE(2026,8,24)+46*7+0) + COUNTIF('08_빅분기_필기_DB'!$I$4:$K$34, DATE(2026,8,24)+46*7+0) + COUNTIF('09_빅분기_실기_DB'!$H$4:$I$25, DATE(2026,8,24)+46*7+0) | AX11: =COUNTIFS('02_SWEA_통합_코딩테스트_DB'!$F$4:$F$1260, DATE(2026,8,24)+47*7+0, '02_SWEA_통합_코딩테스트_DB'!$J$4:$J$1260, "<>보류*") + COUNTIFS('02_SWEA_통합_코딩테스트_DB'!$G$4:$G$1260, DATE(2026,8,24)+47*7+0, '02_SWEA_통합_코딩테스트_DB'!$J$4:$J$1260, "<>보류*") + COUNTIFS('02_SWEA_통합_코딩테스트_DB'!$H$4:$H$1260, DATE(2026,8,24)+47*7+0, '02_SWEA_통합_코딩테스트_DB'!$J$4:$J$1260, "<>보류*") + COUNTIFS('02_SWEA_통합_코딩테스트_DB'!$I$4:$I$1260, DATE(2026,8,24)+47*7+0, '02_SWEA_통합_코딩테스트_DB'!$J$4:$J$1260, "<>보류*") + COUNTIF('03_보안기사_필기_DB'!$I$4:$M$100, DATE(2026,8,24)+47*7+0) + COUNTIF('04_보안기사_실기_DB'!$G$4:$I$30, DATE(2026,8,24)+47*7+0) + COUNTIF('08_빅분기_필기_DB'!$I$4:$K$34, DATE(2026,8,24)+47*7+0) + COUNTIF('09_빅분기_실기_DB'!$H$4:$I$25, DATE(2026,8,24)+47*7+0) | AY11: =COUNTIFS('02_SWEA_통합_코딩테스트_DB'!$F$4:$F$1260, DATE(2026,8,24)+48*7+0, '02_SWEA_통합_코딩테스트_DB'!$J$4:$J$1260, "<>보류*") + COUNTIFS('02_SWEA_통합_코딩테스트_DB'!$G$4:$G$1260, DATE(2026,8,24)+48*7+0, '02_SWEA_통합_코딩테스트_DB'!$J$4:$J$1260, "<>보류*") + COUNTIFS('02_SWEA_통합_코딩테스트_DB'!$H$4:$H$1260, DATE(2026,8,24)+48*7+0, '02_SWEA_통합_코딩테스트_DB'!$J$4:$J$1260, "<>보류*") + COUNTIFS('02_SWEA_통합_코딩테스트_DB'!$I$4:$I$1260, DATE(2026,8,24)+48*7+0, '02_SWEA_통합_코딩테스트_DB'!$J$4:$J$1260, "<>보류*") + COUNTIF('03_보안기사_필기_DB'!$I$4:$M$100, DATE(2026,8,24)+48*7+0) + COUNTIF('04_보안기사_실기_DB'!$G$4:$I$30, DATE(2026,8,24)+48*7+0) + COUNTIF('08_빅분기_필기_DB'!$I$4:$K$34, DATE(2026,8,24)+48*7+0) + COUNTIF('09_빅분기_실기_DB'!$H$4:$I$25, DATE(2026,8,24)+48*7+0) | AZ11: =COUNTIFS('02_SWEA_통합_코딩테스트_DB'!$F$4:$F$1260, DATE(2026,8,24)+49*7+0, '02_SWEA_통합_코딩테스트_DB'!$J$4:$J$1260, "<>보류*") + COUNTIFS('02_SWEA_통합_코딩테스트_DB'!$G$4:$G$1260, DATE(2026,8,24)+49*7+0, '02_SWEA_통합_코딩테스트_DB'!$J$4:$J$1260, "<>보류*") + COUNTIFS('02_SWEA_통합_코딩테스트_DB'!$H$4:$H$1260, DATE(2026,8,24)+49*7+0, '02_SWEA_통합_코딩테스트_DB'!$J$4:$J$1260, "<>보류*") + COUNTIFS('02_SWEA_통합_코딩테스트_DB'!$I$4:$I$1260, DATE(2026,8,24)+49*7+0, '02_SWEA_통합_코딩테스트_DB'!$J$4:$J$1260, "<>보류*") + COUNTIF('03_보안기사_필기_DB'!$I$4:$M$100, DATE(2026,8,24)+49*7+0) + COUNTIF('04_보안기사_실기_DB'!$G$4:$I$30, DATE(2026,8,24)+49*7+0) + COUNTIF('08_빅분기_필기_DB'!$I$4:$K$34, DATE(2026,8,24)+49*7+0) + COUNTIF('09_빅분기_실기_DB'!$H$4:$I$25, DATE(2026,8,24)+49*7+0) | BA11: =COUNTIFS('02_SWEA_통합_코딩테스트_DB'!$F$4:$F$1260, DATE(2026,8,24)+50*7+0, '02_SWEA_통합_코딩테스트_DB'!$J$4:$J$1260, "<>보류*") + COUNTIFS('02_SWEA_통합_코딩테스트_DB'!$G$4:$G$1260, DATE(2026,8,24)+50*7+0, '02_SWEA_통합_코딩테스트_DB'!$J$4:$J$1260, "<>보류*") + COUNTIFS('02_SWEA_통합_코딩테스트_DB'!$H$4:$H$1260, DATE(2026,8,24)+50*7+0, '02_SWEA_통합_코딩테스트_DB'!$J$4:$J$1260, "<>보류*") + COUNTIFS('02_SWEA_통합_코딩테스트_DB'!$I$4:$I$1260, DATE(2026,8,24)+50*7+0, '02_SWEA_통합_코딩테스트_DB'!$J$4:$J$1260, "<>보류*") + COUNTIF('03_보안기사_필기_DB'!$I$4:$M$100, DATE(2026,8,24)+50*7+0) + COUNTIF('04_보안기사_실기_DB'!$G$4:$I$30, DATE(2026,8,24)+50*7+0) + COUNTIF('08_빅분기_필기_DB'!$I$4:$K$34, DATE(2026,8,24)+50*7+0) + COUNTIF('09_빅분기_실기_DB'!$H$4:$I$25, DATE(2026,8,24)+50*7+0) | BB11: =COUNTIFS('02_SWEA_통합_코딩테스트_DB'!$F$4:$F$1260, DATE(2026,8,24)+51*7+0, '02_SWEA_통합_코딩테스트_DB'!$J$4:$J$1260, "<>보류*") + COUNTIFS('02_SWEA_통합_코딩테스트_DB'!$G$4:$G$1260, DATE(2026,8,24)+51*7+0, '02_SWEA_통합_코딩테스트_DB'!$J$4:$J$1260, "<>보류*") + COUNTIFS('02_SWEA_통합_코딩테스트_DB'!$H$4:$H$1260, DATE(2026,8,24)+51*7+0, '02_SWEA_통합_코딩테스트_DB'!$J$4:$J$1260, "<>보류*") + COUNTIFS('02_SWEA_통합_코딩테스트_DB'!$I$4:$I$1260, DATE(2026,8,24)+51*7+0, '02_SWEA_통합_코딩테스트_DB'!$J$4:$J$1260, "<>보류*") + COUNTIF('03_보안기사_필기_DB'!$I$4:$M$100, DATE(2026,8,24)+51*7+0) + COUNTIF('04_보안기사_실기_DB'!$G$4:$I$30, DATE(2026,8,24)+51*7+0) + COUNTIF('08_빅분기_필기_DB'!$I$4:$K$34, DATE(2026,8,24)+51*7+0) + COUNTIF('09_빅분기_실기_DB'!$H$4:$I$25, DATE(2026,8,24)+51*7+0) | BC11: =COUNTIFS('02_SWEA_통합_코딩테스트_DB'!$F$4:$F$1260, DATE(2026,8,24)+52*7+0, '02_SWEA_통합_코딩테스트_DB'!$J$4:$J$1260, "<>보류*") + COUNTIFS('02_SWEA_통합_코딩테스트_DB'!$G$4:$G$1260, DATE(2026,8,24)+52*7+0, '02_SWEA_통합_코딩테스트_DB'!$J$4:$J$1260, "<>보류*") + COUNTIFS('02_SWEA_통합_코딩테스트_DB'!$H$4:$H$1260, DATE(2026,8,24)+52*7+0, '02_SWEA_통합_코딩테스트_DB'!$J$4:$J$1260, "<>보류*") + COUNTIFS('02_SWEA_통합_코딩테스트_DB'!$I$4:$I$1260, DATE(2026,8,24)+52*7+0, '02_SWEA_통합_코딩테스트_DB'!$J$4:$J$1260, "<>보류*") + COUNTIF('03_보안기사_필기_DB'!$I$4:$M$100, DATE(2026,8,24)+52*7+0) + COUNTIF('04_보안기사_실기_DB'!$G$4:$I$30, DATE(2026,8,24)+52*7+0)
